<?xml version="1.0" encoding="UTF-8"?>
<sdf version='1.9'>
  <model name='quad_plus'>
    <pose>0 0 .24 0 0 0</pose>
    <self_collide>false</self_collide>
    <static>false</static>
    <link name="base_link">
      <inertial>
        <mass>2.0</mass>
        <inertia>
          <ixx>0.02166666666666667</ixx>
          <ixy>0</ixy>
          <ixz>0</ixz>
          <iyy>0.02166666666666667</iyy>
          <iyz>0</iyz>
          <izz>0.04000000000000001</izz>
        </inertia>
      </inertial>
      <gravity>true</gravity>
      <velocity_decay />
      
      <material name="CarbonFiberTexture">
        <script>
          <uri>file://media/materials/scripts/gazebo.material</uri> 
          <name>Gazebo/CarbonFiber</name> 
        </script>
      </material>
      
      <visual name="hub_center_visual">
        <pose>0 0 0.06 0 0 0</pose>
        <geometry>
          <box>
            <size>0.05 0.05 0.02</size>
          </box>
        </geometry>
        <material>${material:CarbonFiberTexture}</material> </visual>
      <collision name="hub_center_collision">
        <pose>0 0 0.06 0 0 0</pose>
        <geometry>
          <box>
            <size>0.05 0.05 0.02</size>
          </box>
        </geometry>
      </collision>

      <visual name="arm_x_plus_visual">
        <pose>0.1185 0 0.06 0 0 0</pose>
        <geometry>
          <box>
            <size>0.237 0.02 0.02</size>
          </box>
        </geometry>
        <material>${material:CarbonFiberTexture}</material> </visual>
      <collision name="arm_x_plus_collision">
        <pose>0.1185 0 0.06 0 0 0</pose>
        <geometry>
          <box>
            <size>0.237 0.02 0.02</size>
          </box>
        </geometry>
      </collision>

      <visual name="arm_x_minus_visual">
        <pose>-0.1185 0 0.06 0 0 0</pose>
        <geometry>
          <box>
            <size>0.237 0.02 0.02</size>
          </box>
        </geometry>
        <material>${material:CarbonFiberTexture}</material> </visual>
      <collision name="arm_x_minus_collision">
        <pose>-0.1185 0 0.06 0 0 0</pose>
        <geometry>
          <box>
            <size>0.237 0.02 0.02</size>
          </box>
        </geometry>
      </collision>

      <visual name="arm_y_plus_visual">
        <pose>0 0.1185 0.06 0 0 1.57079632679</pose>
        <geometry>
          <box>
            <size>0.237 0.02 0.02</size>
          </box>
        </geometry>
        <material>${material:CarbonFiberTexture}</material> </visual>
      <collision name="arm_y_plus_collision">
        <pose>0 0.1185 0.06 0 0 1.57079632679</pose>
        <geometry>
          <box>
            <size>0.237 0.02 0.02</size>
          </box>
        </geometry>
      </collision>

      <visual name="arm_y_minus_visual">
        <pose>0 -0.1185 0.06 0 0 1.57079632679</pose>
        <geometry>
          <box>
            <size>0.237 0.02 0.02</size>
          </box>
        </geometry>
        <material>${material:CarbonFiberTexture}</material> </visual>
      <collision name="arm_y_minus_collision">
        <pose>0 -0.1185 0.06 0 0 1.57079632679</pose>
        <geometry>
          <box>
            <size>0.237 0.02 0.02</size>
          </box>
        </geometry>
      </collision>

      <visual name="foot_0">
        <pose>0.1185 0 -0.09 0 0 0</pose>
        <geometry>
          <box>
            <size>0.02 0.02 0.3</size>
          </box>
        </geometry>
      </visual>
      <collision name="foot_0_collision">
        <pose>0.1185 0 -0.09 0 0 0</pose>
        <geometry>
          <box>
            <size>0.02 0.02 0.3</size>
          </box>
        </geometry>
      </collision>

      <visual name="foot_1">
        <pose>-0.1185 0 -0.09 0 0 0</pose>
        <geometry>
          <box>
            <size>0.02 0.02 0.3</size>
          </box>
        </geometry>
      </visual>
      <collision name="foot_1_collision">
        <pose>-0.1185 0 -0.09 0 0 0</pose>
        <geometry>
          <box>
            <size>0.02 0.02 0.3</size>
          </box>
        </geometry>
      </collision>

      <visual name="foot_2">
        <pose>0 0.1185 -0.09 0 0 0</pose>
        <geometry>
          <box>
            <size>0.02 0.02 0.3</size>
          </box>
        </geometry>
      </visual>
      <collision name="foot_2_collision">
        <pose>0 0.1185 -0.09 0 0 0</pose>
        <geometry>
          <box>
            <size>0.02 0.02 0.3</size>
          </box>
        </geometry>
      </collision>

      <visual name="foot_3">
        <pose>0 -0.1185 -0.09 0 0 0</pose>
        <geometry>
          <box>
            <size>0.02 0.02 0.3</size>
          </box>
        </geometry>
      </visual>
      <collision name="foot_3_collision">
        <pose>0 -0.1185 -0.09 0 0 0</pose>
        <geometry>
          <box>
            <size>0.02 0.02 0.3</size>
          </box>
        </geometry>
      </collision>

      <sensor name="air_pressure_sensor" type="air_pressure">
        <gz_frame_id>base_link</gz_frame_id>
        <always_on>1</always_on>
        <update_rate>50</update_rate>
        <air_pressure>
          <pressure>
            <noise type="gaussian">
              <mean>0</mean>
              <stddev>3</stddev>
            </noise>
          </pressure>
        </air_pressure>
      </sensor>
      <sensor name="magnetometer_sensor" type="magnetometer">
        <gz_frame_id>base_link</gz_frame_id>
        <always_on>1</always_on>
        <update_rate>100</update_rate>
        <magnetometer>
          <x>
            <noise type="gaussian">
              <stddev>0.0001</stddev>
            </noise>
          </x>
          <y>
            <noise type="gaussian">
              <stddev>0.0001</stddev>
            </noise>
          </y>
          <z>
            <noise type="gaussian">
              <stddev>0.0001</stddev>
            </noise>
          </z>
        </magnetometer>
      </sensor>
      <sensor name="imu_sensor" type="imu">
        <gz_frame_id>base_link</gz_frame_id>
        <always_on>1</always_on>
        <update_rate>250</update_rate>
        <imu>
          <angular_velocity>
            <x>
              <noise type="gaussian">
                <mean>0.0</mean>
                <stddev>0.0008726646</stddev>
              </noise>
            </x>
            <y>
              <noise type="gaussian">
                <mean>0.0</mean>
                <stddev>0.0008726646</stddev>
              </noise>
            </y>
            <z>
              <noise type="gaussian">
                <mean>0.0</mean>
                <stddev>0.0008726646</stddev>
              </noise>
            </z>
          </angular_velocity>
          <linear_acceleration>
            <x>
              <noise type="gaussian">
                <mean>0.0</mean>
                <stddev>0.00637</stddev>
              </noise>
            </x>
            <y>
              <noise type="gaussian">
                <mean>0.0</mean>
                <stddev>0.00637</stddev>
              </noise>
            </y>
            <z>
              <noise type="gaussian">
                <mean>0.0</mean>
                <stddev>0.00686</stddev>
              </noise>
            </z>
          </linear_acceleration>
        </imu>
      </sensor>
      <sensor name="navsat_sensor" type="navsat">
        <gz_frame_id>base_link</gz_frame_id>
        <always_on>1</always_on>
        <update_rate>30</update_rate>
      </sensor>
    </link>
    <link name="rotor_0">
      <gravity>true</gravity>
      <self_collide>false</self_collide>
      <velocity_decay />
      <pose>0.237 0 0.09 0 0 0</pose>
      <inertial>
        <mass>0.016076923076923075</mass>
        <inertia>
          <ixx>3.8464910483993325e-07</ixx>
          <iyy>2.6115851691700804e-05</iyy>
          <izz>2.649858234714004e-05</izz>
        </inertia>
      </inertial>
      <visual name="rotor_0_visual">
        <pose>-0.022 -0.14638461538461536 -0.016 0 0 0</pose>
        <geometry>
          <mesh>
            <scale>0.8461538461538461 0.8461538461538461 0.8461538461538461</scale>
            <uri>model://quad_plus/meshes/1345_prop_ccw.stl</uri>
          </mesh>
        </geometry>
        <material>
          <script>
            <name>Gazebo/DarkGrey</name>
            <uri>file://media/materials/scripts/gazebo.material</uri>
          </script>
        </material>
      </visual>
      <visual name="rotor_0_visual_motor_bell">
        <pose>0 0 -.032 0 0 0</pose>
        <geometry>
          <mesh>
            <scale>1 1 1</scale>
            <uri>model://quad_plus/meshes/5010Bell.dae</uri>
          </mesh>
        </geometry>
      </visual>
      <collision name="rotor_0_collision">
        <pose>0 0 0 0 0 0 </pose>
        <geometry>
          <box>
            <size>0.2792307692307692 0.016923076923076923 0.0008461538461538462</size>
          </box>
        </geometry>
        <surface>
          <contact>
            <ode>
              <min_depth>0.001</min_depth>
              <max_vel>0</max_vel>
            </ode>
          </contact>
          <friction>
            <ode />
          </friction>
        </surface>
      </collision>
    </link>
    <joint name="rotor_0_joint" type="revolute">
      <parent>base_link</parent>
      <child>rotor_0</child>
      <axis>
        <xyz>0 0 1</xyz>
        <limit>
          <lower>-1e+16</lower>
          <upper>1e+16</upper>
        </limit>
        <dynamics>
          <spring_reference>0</spring_reference>
          <spring_stiffness>0</spring_stiffness>
        </dynamics>
      </axis>
    </joint>
    <link name="rotor_1">
      <gravity>true</gravity>
      <self_collide>false</self_collide>
      <velocity_decay />
      <pose>-0.237 0 0.09 0 0 0</pose>
      <inertial>
        <mass>0.016076923076923075</mass>
        <inertia>
          <ixx>3.8464910483993325e-07</ixx>
          <iyy>2.6115851691700804e-05</iyy>
          <izz>2.649858234714004e-05</izz>
        </inertia>
      </inertial>
      <visual name="rotor_1_visual">
        <pose>-0.022 -0.14638461538461536 -0.016 0 0 0</pose>
        <geometry>
          <mesh>
            <scale>0.8461538461538461 0.8461538461538461 0.8461538461538461</scale>
            <uri>model://quad_plus/meshes/1345_prop_ccw.stl</uri>
          </mesh>
        </geometry>
        <material>
          <script>
            <name>Gazebo/DarkGrey</name>
            <uri>file://media/materials/scripts/gazebo.material</uri>
          </script>
        </material>
      </visual>
      <visual name="rotor_1_visual_motor_top">
        <pose>0 0 -.032 0 0 0</pose>
        <geometry>
          <mesh>
            <scale>1 1 1</scale>
            <uri>model://quad_plus/meshes/5010Bell.dae</uri>
          </mesh>
        </geometry>
      </visual>
      <collision name="rotor_1_collision">
        <pose>0 0 0 0 0 0 </pose>
        <geometry>
          <box>
            <size>0.2792307692307692 0.016923076923076923 0.0008461538461538462</size>
          </box>
        </geometry>
        <surface>
          <contact>
            <ode>
              <min_depth>0.001</min_depth>
              <max_vel>0</max_vel>
            </ode>
          </contact>
          <friction>
            <ode />
          </friction>
        </surface>
      </collision>
    </link>
    <joint name="rotor_1_joint" type="revolute">
      <parent>base_link</parent>
      <child>rotor_1</child>
      <axis>
        <xyz>0 0 1</xyz>
        <limit>
          <lower>-1e+16</lower>
          <upper>1e+16</upper>
        </limit>
        <dynamics>
          <spring_reference>0</spring_reference>
          <spring_stiffness>0</spring_stiffness>
        </dynamics>
      </axis>
    </joint>
    <link name="rotor_2">
      <gravity>true</gravity>
      <self_collide>false</self_collide>
      <velocity_decay />
      <pose>0 0.237 0.09 0 0 0</pose>
      <inertial>
        <mass>0.016076923076923075</mass>
        <inertia>
          <ixx>3.8464910483993325e-07</ixx>
          <iyy>2.6115851691700804e-05</iyy>
          <izz>2.649858234714004e-05</izz>
        </inertia>
      </inertial>
      <visual name="rotor_2_visual">
        <pose>-0.022 -0.14638461538461536 -0.016 0 0 0</pose>
        <geometry>
          <mesh>
            <scale>0.8461538461538461 0.8461538461538461 0.8461538461538461</scale>
            <uri>model://quad_plus/meshes/1345_prop_cw.stl</uri>
          </mesh>
        </geometry>
        <material>
          <script>
            <name>Gazebo/DarkGrey</name>
            <uri>file://media/materials/scripts/gazebo.material</uri>
          </script>
        </material>
      </visual>
      <visual name="rotor_2_visual_motor_top">
        <pose>0 0 -.032 0 0 0</pose>
        <geometry>
          <mesh>
            <scale>1 1 1</scale>
            <uri>model://quad_plus/meshes/5010Bell.dae</uri>
          </mesh>
        </geometry>
      </visual>
      <collision name="rotor_2_collision">
        <pose>0 0 0 0 0 0 </pose>
        <geometry>
          <box>
            <size>0.2792307692307692 0.016923076923076923 0.0008461538461538462</size>
          </box>
        </geometry>
        <surface>
          <contact>
            <ode>
              <min_depth>0.001</min_depth>
              <max_vel>0</max_vel>
            </ode>
          </contact>
          <friction>
            <ode />
          </friction>
        </surface>
      </collision>
    </link>
    <joint name="rotor_2_joint" type="revolute">
      <parent>base_link</parent>
      <child>rotor_2</child>
      <axis>
        <xyz>0 0 1</xyz>
        <limit>
          <lower>-1e+16</lower>
          <upper>1e+16</upper>
        </limit>
        <dynamics>
          <spring_reference>0</spring_reference>
          <spring_stiffness>0</spring_stiffness>
        </dynamics>
      </axis>
    </joint>
    <link name="rotor_3">
      <gravity>true</gravity>
      <self_collide>false</self_collide>
      <velocity_decay />
      <pose>0 -0.237 0.09 0 0 0</pose>
      <inertial>
        <mass>0.016076923076923075</mass>
        <inertia>
          <ixx>3.8464910483993325e-07</ixx>
          <iyy>2.6115851691700804e-05</iyy>
          <izz>2.649858234714004e-05</izz>
        </inertia>
      </inertial>
      <visual name="rotor_3_visual">
        <pose>-0.022 -0.14638461538461536 -0.016 0 0 0</pose>
        <geometry>
          <mesh>
            <scale>0.8461538461538461 0.8461538461538461 0.8461538461538461</scale>
            <uri>model://quad_plus/meshes/1345_prop_cw.stl</uri>
          </mesh>
        </geometry>
        <material>
          <script>
            <name>Gazebo/DarkGrey</name>
            <uri>file://media/materials/scripts/gazebo.material</uri>
          </script>
        </material>
      </visual>
      <visual name="rotor_3_visual_motor_top">
        <pose>0 0 -.032 0 0 0</pose>
        <geometry>
          <mesh>
            <scale>1 1 1</scale>
            <uri>model://quad_plus/meshes/5010Bell.dae</uri>
          </mesh>
        </geometry>
      </visual>
      <collision name="rotor_3_collision">
        <pose>0 0 0 0 0 0 </pose>
        <geometry>
          <box>
            <size>0.2792307692307692 0.016923076923076923 0.0008461538461538462</size>
          </box>
        </geometry>
        <surface>
          <contact>
            <ode>
              <min_depth>0.001</min_depth>
              <max_vel>0</max_vel>
            </ode>
          </contact>
          <friction>
            <ode />
          </friction>
        </surface>
      </collision>
    </link>
    <joint name="rotor_3_joint" type="revolute">
      <parent>base_link</parent>
      <child>rotor_3</child>
      <axis>
        <xyz>0 0 1</xyz>
        <limit>
          <lower>-1e+16</lower>
          <upper>1e+16</upper>
        </limit>
        <dynamics>
          <spring_reference>0</spring_reference>
          <spring_stiffness>0</spring_stiffness>
        </dynamics>
      </axis>
    </joint>
      
    <plugin filename="gz-sim-multicopter-motor-model-system"
      name="gz::sim::systems::MulticopterMotorModel">
      <jointName>rotor_0_joint</jointName>
      <linkName>rotor_0</linkName>
      <turningDirection>ccw</turningDirection>
      <timeConstantUp>0.0125</timeConstantUp>
      <timeConstantDown>0.025</timeConstantDown>
      <maxRotVelocity>1000.0</maxRotVelocity>
      <motorConstant>8.54858e-06</motorConstant>
      <momentConstant>0.016</momentConstant>
      <commandSubTopic>command/motor_speed</commandSubTopic>
      <motorNumber>0</motorNumber>
      <rotorDragCoefficient>8.06428e-05</rotorDragCoefficient>
      <rollingMomentCoefficient>1e-06</rollingMomentCoefficient>
      <rotorVelocitySlowdownSim>10</rotorVelocitySlowdownSim>
      <motorType>velocity</motorType>
    </plugin>
    <plugin filename="gz-sim-multicopter-motor-model-system"
      name="gz::sim::systems::MulticopterMotorModel">
      <jointName>rotor_1_joint</jointName>
      <linkName>rotor_1</linkName>
      <turningDirection>ccw</turningDirection>
      <timeConstantUp>0.0125</timeConstantUp>
      <timeConstantDown>0.025</timeConstantDown>
      <maxRotVelocity>1000.0</maxRotVelocity>
      <motorConstant>8.54858e-06</motorConstant>
      <momentConstant>0.016</momentConstant>
      <commandSubTopic>command/motor_speed</commandSubTopic>
      <motorNumber>1</motorNumber>
      <rotorDragCoefficient>8.06428e-05</rotorDragCoefficient>
      <rollingMomentCoefficient>1e-06</rollingMomentCoefficient>
      <rotorVelocitySlowdownSim>10</rotorVelocitySlowdownSim>
      <motorType>velocity</motorType>
    </plugin>
    <plugin filename="gz-sim-multicopter-motor-model-system"
      name="gz::sim::systems::MulticopterMotorModel">
      <jointName>rotor_2_joint</jointName>
      <linkName>rotor_2</linkName>
      <turningDirection>cw</turningDirection>
      <timeConstantUp>0.0125</timeConstantUp>
      <timeConstantDown>0.025</timeConstantDown>
      <maxRotVelocity>1000.0</maxRotVelocity>
      <motorConstant>8.54858e-06</motorConstant>
      <momentConstant>0.016</momentConstant>
      <commandSubTopic>command/motor_speed</commandSubTopic>
      <motorNumber>2</motorNumber>
      <rotorDragCoefficient>8.06428e-05</rotorDragCoefficient>
      <rollingMomentCoefficient>1e-06</rollingMomentCoefficient>
      <rotorVelocitySlowdownSim>10</rotorVelocitySlowdownSim>
      <motorType>velocity</motorType>
    </plugin>
    <plugin filename="gz-sim-multicopter-motor-model-system"
      name="gz::sim::systems::MulticopterMotorModel">
      <jointName>rotor_3_joint</jointName>
      <linkName>rotor_3</linkName>
      <turningDirection>cw</turningDirection>
      <timeConstantUp>0.0125</timeConstantUp>
      <timeConstantDown>0.025</timeConstantDown>
      <maxRotVelocity>1000.0</maxRotVelocity>
      <motorConstant>8.54858e-06</motorConstant>
      <momentConstant>0.016</momentConstant>
      <commandSubTopic>command/motor_speed</commandSubTopic>
      <motorNumber>3</motorNumber>
      <rotorDragCoefficient>8.06428e-05</rotorDragCoefficient>
      <rollingMomentCoefficient>1e-06</rollingMomentCoefficient>
      <rotorVelocitySlowdownSim>10</rotorVelocitySlowdownSim>
      <motorType>velocity</motorType>
    </plugin>
    <plugin filename="MotorFailurePlugin"
      name="gz::sim::systems::MotorFailureSystem">
    </plugin>
  </model>
  
</sdf>
